<?xml version="1.0" ?>
<robot name = "surgical_robot">

      <material name="transparent">
        <color rgba="0 0 .5 .2"/>
      </material>

      <material name="red">
        <color rgba="1 0 0 1"/>
      </material>

      <material name="green">
        <color rgba="0 1 0 1"/>
      </material>

      <material name="blue">
        <color rgba="0 0 1 1"/>
      </material>

      <material name="yellow">
        <color rgba="1 1 0 1"/>
      </material>

      <material name="magenta">
        <color rgba="1 0 1 1"/>
      </material>

      <material name="cyan">
        <color rgba="0 1 1 1"/>
      </material>
      
  <link name="base_link">
      <visual>
	<geometry>
	  <mesh filename="package://surgical_robot_description/meshes/MRI.stl" />
	</geometry>
      <material name="transparent"/>
      </visual>
      <collision>
        <geometry>
	  <mesh filename="package://surgical_robot_description/meshes/MRI.stl"/>
        </geometry>
      </collision>
  </link>
  <link name="axial_translation">
      <collision name="axial_translation_geom">
        <geometry>
	  <mesh filename="package://surgical_robot_description/meshes/axial_translation.stl" />
        </geometry>
      </collision>
      <visual name="axial_translation_visual">
      <geometry>
	  <mesh filename="package://surgical_robot_description/meshes/axial_translation.stl" />
	</geometry>
	<material name="red"/>
      </visual>
    </link>
  <link name="lateral_translation">
      <collision name="lateral_translation_geom">
        <geometry>
	  <mesh filename="package://surgical_robot_description/meshes/lateral_translation.stl" />
        </geometry>
      </collision>
      <visual name="lateral_translation_visual">
	<geometry>
	  <mesh filename="package://surgical_robot_description/meshes/lateral_translation.stl" />
	</geometry>
	<material name="blue"/>
	</visual>
    </link>
  <link name="vertical_translation">
      <collision name="vertical_translation_geom">
        <geometry>
	  <mesh filename="package://surgical_robot_description/meshes/vertical_translation.stl" />
        </geometry>
      </collision>
      <visual name="vertical_translation_visual">
	<geometry>
	  <mesh filename="package://surgical_robot_description/meshes/vertical_translation.stl" />
	</geometry>
	<material name="green"/>
      </visual>
    </link>
  
    
    <link name="base">
      <collision name="base_geom">
        <geometry>
	  <mesh filename="package://surgical_robot_description/meshes/base.stl" />
        </geometry>
      </collision>
      <visual name="base_visual">
	<geometry>
	  <mesh filename="package://surgical_robot_description/meshes/base.stl" />
	</geometry>
	<material name="yellow"/>
      </visual>
    </link>

    <link name="base_yaw">
      <collision name="base_yaw_geom">
        <geometry>
	  <mesh filename="package://surgical_robot_description/meshes/base_yaw.stl" />
        </geometry>
      </collision>
      <visual name="base_yaw_visual">
	<geometry>
	  <mesh filename="package://surgical_robot_description/meshes/base_yaw.stl" />
	<material name="yellow"/>
	</geometry>
      </visual>
    </link>

    <link name="vertical_long">
      <collision name="vertical_long_geom">
        <geometry>
	  <mesh filename="package://surgical_robot_description/meshes/vertical_long.stl" />
        </geometry>
      </collision>
      <visual name="vertical_long_visual">
	<geometry>
	  <mesh filename="package://surgical_robot_description/meshes/vertical_long.stl" />
	</geometry>
	<material name="magenta"/>
      </visual>
    </link>
    
      <link name="vertical_short">
      <collision name="vertical_short_geom">
        <geometry>
	  <mesh filename="package://surgical_robot_description/meshes/vertical_short.stl" />
        </geometry>
      </collision>
      <visual name="vertical_short_visual">
	<geometry>
	  <mesh filename="package://surgical_robot_description/meshes/vertical_short.stl" />
	</geometry>
	<material name="magenta"/>
      </visual>
    </link>

    
    <link name="horizontal_long">
      <collision name="horizontal_long_geom">
        <geometry>
	  <mesh filename="package://surgical_robot_description/meshes/horizontal_long.stl" />
        </geometry>
      </collision>
      <visual name="horizontal_long_visual">
	<geometry>
	  <mesh filename="package://surgical_robot_description/meshes/horizontal_long.stl" />
	</geometry>
	<material name="cyan"/>
      </visual>
    </link>
    
      <link name="horizontal_short">
      <collision name="horizontal_short_geom">
        <geometry>
	  <mesh filename="package://surgical_robot_description/meshes/horizontal_short.stl" />
        </geometry>
      </collision>
      <visual name="horizontal_short_visual">
	<geometry>
	  <mesh filename="package://surgical_robot_description/meshes/horizontal_short.stl" />
	</geometry>
	<material name="cyan"/>
      </visual>
    </link>
  
      <link name="needle_driver">
      <collision name="needle_driver_geom">
        <geometry>
	  <mesh filename="package://surgical_robot_description/meshes/needle_driver.stl" />
        </geometry>
      </collision>
      <visual name="needle_driver_visual">
	<geometry>
	  <mesh filename="package://surgical_robot_description/meshes/needle_driver.stl" />
	</geometry>
	<material name="red"/>
      </visual>
    </link>
   
 <joint name="joint1" type="fixed">
    <parent link="base_link"/>
    <child link="axial_translation"/>
    
    <origin xyz="-0.021 0.01395 -0.04806 " rpy="0 0 0" />
    
</joint>

 <joint name="joint2" type="prismatic">
    <parent link="axial_translation"/>
    <child link="lateral_translation"/>
    
    <origin xyz="0.006  0.00995 -0.055" rpy="0 0 0" />    
    <limit lower="0" upper="0.1" effort="0.001" velocity="0.2" />
    <axis xyz= "1 0 0"/>
</joint>

 <joint name="joint3" type="prismatic">
    <parent link="lateral_translation"/>
    <child link="vertical_translation"/>
    
    <origin xyz="0.0343 0.01195 -0.0054" rpy="0 0 0" />
    <limit lower="0" upper="0.1" effort="0.001" velocity="0.2" />
        <axis xyz= "0 1 0"/>
</joint>

 <joint name="joint4" type="prismatic">
    <parent link="vertical_translation"/>
    <child link="base"/>
    
    <origin xyz="0.011 0.04381 0.007" rpy="0 0 0" />
    <limit lower="0" upper="0.1" effort="0.001" velocity="0.2" />
    <axis xyz= "0 0 1"/>

</joint>

 <joint name="joint5" type="fixed">
    <parent link="base"/>
    <child link="base_yaw"/>
    
    <origin xyz="0.0492 0.07602 -0.131" rpy="0 0 0" />
</joint>

 <joint name="joint6" type="fixed">
    <parent link="base_yaw"/>
    <child link="vertical_long"/>
    
    <origin xyz="0.00724 0.02398 0.0821" rpy="0 0 0" />
</joint>

<joint name="joint7" type="fixed">
    <parent link="base_yaw"/>
    <child link="vertical_short"/>
    
    <origin xyz="-0.01126 0.02398 0.0901" rpy="0 0 0" />
</joint>

<joint name="joint8" type="fixed">
    <parent link="vertical_long"/>
    <child link="horizontal_long"/>
    
    <origin xyz="0 0.08 0.01639" rpy="0 0 0" />
</joint>


<joint name="joint9" type="fixed">
    <parent link="vertical_long"/>
    <child link="horizontal_short"/>
    
    <origin xyz="0 0.0985 0.0085" rpy="0 0 0" />
</joint>

<joint name="joint10" type="fixed">
    <parent link="vertical_short"/>
    <child link="horizontal_long"/>
    
    <origin xyz="0.0185 0.08 0.00839" rpy="0 0 0" />
</joint>

<joint name="joint11" type="fixed">
    <parent link="horizontal_long"/>
    <child link="needle_driver"/>
    
    <origin xyz="0.16 0.0185 -0.01508" rpy="0 0 0" />
</joint>

<joint name="joint12" type="fixed">
    <parent link="horizontal_short"/>
    <child link="needle_driver"/>
    
    <origin xyz="0.16 0 -0.00719" rpy="0 0 0" />
</joint>


</robot>
  
