<?xml version="1.0" ?>
<robot name = "surgical_robot_description">

      <material name="transparent">
        <color rgba="0 0 .5 .2"/>
      </material>

      <material name="red">
        <color rgba="1 0 0 1"/>
      </material>

      <material name="green">
        <color rgba="0 1 0 1"/>
      </material>

      <material name="blue">
        <color rgba="0 0 1 1"/>
      </material>

      <material name="yellow">
        <color rgba="1 1 0 1"/>
      </material>

      <material name="magenta">
        <color rgba="1 0 1 1"/>
      </material>

      <material name="cyan">
        <color rgba="0 1 1 1"/>
      </material>
      
  <link name="base_link">
      <visual>
	<geometry>
	  <mesh filename="package://surgical_robot_description/meshes/MRI.stl" />
	</geometry>
      <material name="transparent"/>
      </visual>
      <collision>
        <geometry>
	  <mesh filename="package://surgical_robot_description/meshes/MRI_2000.stl"/>
        </geometry>
      </collision>
	  <inertial>
		<mass value="0.5"/>
		<inertia ixx="0.001" ixy="0.0" ixz="0.0" iyy="0.001" iyz="0.0" izz="0.001"/>
	  </inertial>
  </link>
  <link name="axial_translation">
      <collision name="axial_translation_geom">
        <geometry>
	  <mesh filename="package://surgical_robot_description/meshes/axial_translation.stl" />
        </geometry>
      </collision>
	  	 <inertial>
		 <mass value="0.5"/>
		 <inertia ixx="0.001" ixy="0.0" ixz="0.0" iyy="0.001" iyz="0.0" izz="0.001"/>
	     </inertial>
      <visual name="axial_translation_visual">
      <geometry>
	  <mesh filename="package://surgical_robot_description/meshes/axial_translation_200.stl" />
	</geometry>
	<material name="red"/>
      </visual>
    </link>
  <link name="lateral_translation">
      <collision name="lateral_translation_geom">
        <geometry>
	  <mesh filename="package://surgical_robot_description/meshes/lateral_translation.stl" />
        </geometry>
      </collision>
	  	 <inertial>
		 <mass value="0.5"/>
		 <inertia ixx="0.001" ixy="0.0" ixz="0.0" iyy="0.001" iyz="0.0" izz="0.001"/>
	     </inertial>
      <visual name="lateral_translation_visual">
	<geometry>
	  <mesh filename="package://surgical_robot_description/meshes/lateral_translation_200.stl" />
	</geometry>
	<material name="blue"/>
	</visual>
    </link>
  <link name="vertical_translation">
      <collision name="vertical_translation_geom">
        <geometry>
	  <mesh filename="package://surgical_robot_description/meshes/vertical_translation.stl" />
        </geometry>
      </collision>
	  	 <inertial>
		 <mass value="0.5"/>
		 <inertia ixx="0.001" ixy="0.0" ixz="0.0" iyy="0.001" iyz="0.0" izz="0.001"/>
	     </inertial>
      <visual name="vertical_translation_visual">
	<geometry>
	  <mesh filename="package://surgical_robot_description/meshes/vertical_translation_200.stl" />
	</geometry>
	<material name="green"/>
      </visual>
    </link>
  
    
    <link name="base">
      <collision name="base_geom">
        <geometry>
	  <mesh filename="package://surgical_robot_description/meshes/base.stl" />
        </geometry>
      </collision>
	  	 <inertial>
		 <mass value="0.5"/>
		 <inertia ixx="0.001" ixy="0.0" ixz="0.0" iyy="0.001" iyz="0.0" izz="0.001"/>
	     </inertial>
      <visual name="base_visual">
	<geometry>
	  <mesh filename="package://surgical_robot_description/meshes/base_200.stl" />
	</geometry>
	<material name="yellow"/>
      </visual>
    </link>

    <link name="base_yaw">
      <collision name="base_yaw_geom">
        <geometry>
	  <mesh filename="package://surgical_robot_description/meshes/base_yaw.stl" />
        </geometry>
      </collision>
	  	 <inertial>
		 <mass value="0.5"/>
		 <inertia ixx="0.001" ixy="0.0" ixz="0.0" iyy="0.001" iyz="0.0" izz="0.001"/>
	     </inertial>
      <visual name="base_yaw_visual">
	<geometry>
	  <mesh filename="package://surgical_robot_description/meshes/base_yaw_200.stl" />
	<material name="yellow"/>
	</geometry>
      </visual>
    </link>

    <link name="vertical_long">
      <collision name="vertical_long_geom">
        <geometry>
	  <mesh filename="package://surgical_robot_description/meshes/vertical_long.stl" />
        </geometry>
      </collision>
	  	 <inertial>
		 <mass value="0.5"/>
		 <inertia ixx="0.001" ixy="0.0" ixz="0.0" iyy="0.001" iyz="0.0" izz="0.001"/>
	     </inertial>
      <visual name="vertical_long_visual">
	<geometry>
	  <mesh filename="package://surgical_robot_description/meshes/vertical_long_200.stl" />
	</geometry>
	<material name="magenta"/>
      </visual>
    </link>
    
      <link name="vertical_short">
      <collision name="vertical_short_geom">
        <geometry>
	  <mesh filename="package://surgical_robot_description/meshes/vertical_short.stl" />
        </geometry>
      </collision>
	  	 <inertial>
		 <mass value="0.5"/>
		 <inertia ixx="0.001" ixy="0.0" ixz="0.0" iyy="0.001" iyz="0.0" izz="0.001"/>
	     </inertial>
      <visual name="vertical_short_visual">
	<geometry>
	  <mesh filename="package://surgical_robot_description/meshes/vertical_short_200.stl" />
	</geometry>
	<material name="magenta"/>
      </visual>
    </link>

    
    <link name="horizontal_long">
      <collision name="horizontal_long_geom">
        <geometry>
	  <mesh filename="package://surgical_robot_description/meshes/horizontal_long.stl" />
        </geometry>
      </collision>
	  	 <inertial>
		 <mass value="0.5"/>
		 <inertia ixx="0.001" ixy="0.0" ixz="0.0" iyy="0.001" iyz="0.0" izz="0.001"/>
	     </inertial>
      <visual name="horizontal_long_visual">
	<geometry>
	  <mesh filename="package://surgical_robot_description/meshes/horizontal_long_200.stl" />
	</geometry>
	<material name="cyan"/>
      </visual>
    </link>
    
      <link name="horizontal_short">
      <collision name="horizontal_short_geom">
        <geometry>
	  <mesh filename="package://surgical_robot_description/meshes/horizontal_short.stl" />
        </geometry>
      </collision>
	  	 <inertial>
		 <mass value="0.5"/>
		 <inertia ixx="0.001" ixy="0.0" ixz="0.0" iyy="0.001" iyz="0.0" izz="0.001"/>
	     </inertial>
      <visual name="horizontal_short_visual">
	<geometry>
	  <mesh filename="package://surgical_robot_description/meshes/horizontal_short_200.stl" />
	</geometry>
	<material name="cyan"/>
      </visual>
    </link>
  
    <link name="needle_driver">
      <!--collision name="needle_driver_geom">
        <geometry>
	        <mesh filename="package://surgical_robot_description/meshes/needle_driver.stl" />
        </geometry>
      </collision-->
	  	 <inertial>
		 <mass value="0.5"/>
		 <inertia ixx="0.001" ixy="0.0" ixz="0.0" iyy="0.001" iyz="0.0" izz="0.001"/>
	     </inertial>
      <visual name="needle_driver_visual">
	<geometry>
	  <mesh filename="package://surgical_robot_description/meshes/needle_driver_200.stl" />
	</geometry>
	<material name="red"/>
      </visual>
    </link> 

    <link name="needle_link">
      <collision>
        <geometry>
          <cylinder length="0.12" radius="0.0022"/>
        </geometry>
      </collision>
     <visual name="needle_link_visual">
        <geometry>
          <cylinder length="0.12" radius="0.0022"/>
        </geometry>
        <material name="green"/>
      </visual>
    </link>     

    <link name="needle_eef">
      <collision>
        <geometry>
          <cylinder length="0.02" radius="0.0022"/>
        </geometry>
      </collision>
     <visual name="needle_eef_visual">
        <geometry>
          <cylinder length="0.0025" radius="0.0022"/>
        </geometry>
        <material name="red"/>
      </visual>
    </link>   
 <!--link name="world"/>
 
 <joint name="world_link" type="fixed">
    <parent link="world"/>
    <child link="base_link"/>
    <origin xyz="0 0 0" rpy="0 -0.5707 0" />
    <axis xyz="0 -0.5 0"/>
    
</joint-->

 <joint name="joint1" type="fixed">
    <parent link="base_link"/>
    <child link="axial_translation"/>
    <origin xyz="-0.021 0.01395 -0.04806 " rpy="0 0 0" />
    <pose> 0 0 0 0 0 0</pose>    
</joint>

 <joint name="joint2" type="prismatic">
    <parent link="axial_translation"/>
    <child link="lateral_translation"/>
    <pose> 0 0 0 0 0 0</pose>    
    <origin xyz="0.006  0.00995 -0.055" rpy="0 0 0" />    
    <limit lower="0" upper="0.1" effort="0.001" velocity="0.2" />
    <axis xyz= "0 0 1"/>
</joint>

 <joint name="joint3" type="prismatic">
    <parent link="lateral_translation"/>
    <child link="vertical_translation"/>
    <pose> 0 0 0 0 0 0</pose>    
    <origin xyz="0.0343 0.01195 -0.0054" rpy="0 0 0" />
    <limit lower="0" upper="0.1" effort="0.001" velocity="0.2" />
        <axis xyz= "1 0 0"/>
</joint>

 <joint name="joint4" type="prismatic">
    <parent link="vertical_translation"/>
    <child link="base"/>
    <pose> 0 0 0 0 0 0</pose>    
    <origin xyz="0.011 0.04381 0.007" rpy="0 0 0" />
    <limit lower="0" upper="0.1" effort="0.001" velocity="0.2" />
    <axis xyz= "0 1 0"/>

</joint>

 <joint name="joint5" type="revolute">
    <parent link="base"/>
    <child link="base_yaw"/>
    <pose> 0 0 0 0 0 0</pose>    
    <origin xyz="0.0777 0.10202 -0.086" rpy="0 0 0" />
    <limit effort="1000.0" lower="-0.5" upper="0.5" velocity="0.5"/> 
    <axis xyz="1 0 0"/>
</joint>

 <joint name="joint6" type="revolute">
    <parent link="base_yaw"/>
    <child link="vertical_long"/>
    <pose> 0 0 0 0 0 0</pose>    
    <origin xyz="-0.02126 -0.00202 0.0371" rpy="0 0 0" />
    <limit effort="1000.0" lower="-0.5" upper="0.5" velocity="0.5"/> 
    <axis xyz="0 0 1"/>
    <mimic joint="joint7" multiplier="1" offset="0"/>
</joint>

<joint name="joint7" type="revolute">
    <parent link="base_yaw"/>
    <child link="vertical_short"/>
    <pose> 0 0 0 0 0 0</pose>    
    <origin xyz="-0.03976 -0.00202 0.0451" rpy="0 0 0" />
    <limit effort="1000.0" lower="-0.5" upper="0.5" velocity="0.5"/> 
    <axis xyz="0 0 1"/>
     
</joint>

<joint name="joint8" type="revolute">
    <parent link="vertical_long"/>
    <child link="horizontal_long"/>
    <pose> 0 0 0 0 0 0</pose>    
    <origin xyz="0 0.08 0.01639" rpy="0 0 0" />
    <limit effort="1000.0" lower="-0.5" upper="0.5" velocity="0.5"/> 
    <mimic joint="joint7" multiplier="-1" offset="0"/> 
    <axis xyz="0 0 1"/>
</joint>


<joint name="joint9" type="revolute">
    <parent link="vertical_long"/>
    <child link="horizontal_short"/>
    <pose> 0 0 0 0 0 0</pose>    
    <origin xyz="0 0.0985 0.0085" rpy="0 0 0" />
    <limit effort="1000.0" lower="-0.5" upper="0.5" velocity="0.5"/> 
    <axis xyz="0 0 1"/>
    <mimic joint="joint7" multiplier="-1" offset="0"/> 
</joint>

<!--joint name="joint10" type="revolute">
    <parent link="vertical_short"/>
    <child link="horizontal_long"/>
    <pose> 0 0 0 0 0 0</pose>    
    <origin xyz="0.0185 0.08 0.00839" rpy="0 0 0" />
    <limit effort="1000.0" lower="-0.5" upper="0.5" velocity="0.5"/> 
    <axis xyz="0 0 1"/>
</joint -->

<joint name="joint11" type="prismatic">
    <parent link="horizontal_long"/>
    <child link="needle_driver"/>
    <pose> 0 0 0 0 0 0</pose>    
    <origin xyz="0.16 0.0185 -0.01508" rpy="0 0 0" />
    <limit lower="0" upper="0.1" effort="0.001" velocity="0.2" />
    <axis xyz= "0 1 0"/>
</joint>

<joint name="joint12" type="prismatic">
    <parent link="horizontal_short"/>
    <child link="needle_driver"/>
    <pose> 0 0 0 0 0 0</pose>    
    <origin xyz="0.16 0 -0.00719" rpy="0 0 0" />
    <limit lower="0" upper="0.1" effort="0.001" velocity="0.2" />
    <axis xyz= "0 1 0"/>
</joint>

<joint name="joint13" type="revolute">
    <parent link="needle_driver"/>
    <child link="needle_link"/>
    <pose> 0 0 0 0 0 0</pose>    
    <origin xyz="0 -0.03 -0.03719" rpy="1.57 0 0" />
    <limit effort="1000.0" lower="-0.5" upper="0.5" velocity="0.5"/> 
    <axis xyz= "0 1 0"/>
    <mimic joint="joint7" multiplier="1" offset="0"/>
</joint>

<joint name="joint14" type="fixed">
    <parent link="needle_link"/>
    <child link="needle_eef"/>
    <pose> 0 0 0 0 0 0</pose>    
    <origin xyz="0 0 0.06125" rpy="0 0 0" />
</joint>
<!-- 0.16 -0.06 -0.03719 -->
<gazebo>
  <plugin name="gazebo_ros_control" filename="libgazebo_ros_control.so">
    <robotNamespace>/surgical_robot_description</robotNamespace>
  </plugin>
</gazebo>

  <transmission name="tran1">
    <type>transmission_interface/SimpleTransmission</type>
    <joint name="joint2"/>
    <actuator name="motor1">
      <hardwareInterface>EffortJointInterface</hardwareInterface>
      <mechanicalReduction>1</mechanicalReduction>
    </actuator>
  </transmission>

  <transmission name="tran2">
    <type>transmission_interface/SimpleTransmission</type>
    <joint name="joint3"/>
    <actuator name="motor2">
      <hardwareInterface>EffortJointInterface</hardwareInterface>
      <mechanicalReduction>1</mechanicalReduction>
    </actuator>
  </transmission>
  
  <transmission name="tran3">
    <type>transmission_interface/SimpleTransmission</type>
    <joint name="joint4"/>
    <actuator name="motor3">
      <hardwareInterface>EffortJointInterface</hardwareInterface>
      <mechanicalReduction>1</mechanicalReduction>
    </actuator>
  </transmission>

  <transmission name="tran4">
    <type>transmission_interface/SimpleTransmission</type>
    <joint name="joint5"/>
    <actuator name="motor4">
      <hardwareInterface>EffortJointInterface</hardwareInterface>
      <mechanicalReduction>1</mechanicalReduction>
    </actuator>
  </transmission>
  
  <transmission name="tran5">
    <type>transmission_interface/SimpleTransmission</type>
    <joint name="joint7"/>
    <actuator name="motor5">
      <hardwareInterface>EffortJointInterface</hardwareInterface>
      <mechanicalReduction>1</mechanicalReduction>
    </actuator>
  </transmission>
</robot>
  
