<?xml version="1.0" ?>
<sdf version='1.4'>
  <model name='surgical_robot_description'>
    <link name='base_link'>
      <pose>0 0 0 1.5707 -0 3.14</pose>
      <inertial>
        <pose>-0.021 0.01395 -0.04806 0 -0 0</pose>
        <mass>0.5</mass>
        <inertia>
          <ixx>0.001</ixx>
          <ixy>0</ixy>
          <ixz>0</ixz>
          <iyy>0.001</iyy>
          <iyz>0</iyz>
          <izz>0.001</izz>
        </inertia>
      </inertial>
      <collision name='base_link_collision'>
        <pose>0 0 0 0 -0 0</pose>
        <geometry>
          <mesh>
            <scale>1 1 1</scale>
            <uri>model://surgical_robot_description/meshes/MRI_2000.stl</uri>
          </mesh>
        </geometry>
      </collision>
      <collision name='base_link_collision_axial_translation'>
        <pose>-0.021 0.01395 -0.04806 0 -0 0</pose>
        <geometry>
          <mesh>
            <scale>1 1 1</scale>
            <uri>model://surgical_robot_description/meshes/axial_translation.stl</uri>
          </mesh>
        </geometry>
      </collision>
      <visual name='base_link_visual'>
        <pose>0 0 0 0 -0 0</pose>
        <geometry>
          <mesh>
            <scale>1 1 1</scale>
            <uri>model://surgical_robot_description/meshes/MRI.stl</uri>
          </mesh>
        </geometry>
      </visual>
      <visual name='base_link_visual_axial_translation'>
        <pose>-0.021 0.01395 -0.04806 0 -0 0</pose>
        <geometry>
          <mesh>
            <scale>1 1 1</scale>
            <uri>model://surgical_robot_description/meshes/axial_translation_200.stl</uri>
          </mesh>
        </geometry>
      </visual>
      <velocity_decay>
        <linear>0</linear>
        <angular>0</angular>
      </velocity_decay>
    </link>
    <joint name='world_link' type='revolute'>
      <child>base_link</child>
      <parent>world</parent>
      <axis>
        <limit>
          <lower>0</lower>
          <upper>0</upper>
        </limit>
        <dynamics>
          <damping>0</damping>
        </dynamics>
        <xyz>0 0 1</xyz>
      </axis>
    </joint>
    <link name='lateral_translation'>
      <pose>0.0148358 -0.103086 0.0238901 1.5707 -0 3.14</pose>
      <inertial>
        <pose>0 0 0 0 -0 0</pose>
        <mass>0.5</mass>
        <inertia>
          <ixx>0.001</ixx>
          <ixy>0</ixy>
          <ixz>0</ixz>
          <iyy>0.001</iyy>
          <iyz>0</iyz>
          <izz>0.001</izz>
        </inertia>
      </inertial>
      <collision name='lateral_translation_collision'>
        <pose>0 0 0 0 -0 0</pose>
        <geometry>
          <mesh>
            <scale>1 1 1</scale>
            <uri>model://surgical_robot_description/meshes/lateral_translation.stl</uri>
          </mesh>
        </geometry>
      </collision>
      <visual name='lateral_translation_visual'>
        <pose>0 0 0 0 -0 0</pose>
        <geometry>
          <mesh>
            <scale>1 1 1</scale>
            <uri>model://surgical_robot_description/meshes/lateral_translation_200.stl</uri>
          </mesh>
        </geometry>
      </visual>
      <velocity_decay>
        <linear>0</linear>
        <angular>0</angular>
      </velocity_decay>
    </link>
    <joint name='base_x' type='prismatic'>
      <child>lateral_translation</child>
      <parent>base_link</parent>
      <axis>
        <xyz>0.00159265 0.999999 9.63268e-05</xyz>
        <limit>
          <lower>0</lower>
          <upper>0.1</upper>
          <effort>0.001</effort>
          <velocity>0.2</velocity>
        </limit>
        <dynamics/>
      </axis>
    </joint>
    <link name='vertical_translation'>
      <pose>-0.0194727 -0.108433 0.0358396 1.5707 -0 3.14</pose>
      <inertial>
        <pose>0 0 0 0 -0 0</pose>
        <mass>0.5</mass>
        <inertia>
          <ixx>0.001</ixx>
          <ixy>0</ixy>
          <ixz>0</ixz>
          <iyy>0.001</iyy>
          <iyz>0</iyz>
          <izz>0.001</izz>
        </inertia>
      </inertial>
      <collision name='vertical_translation_collision'>
        <pose>0 0 0 0 -0 0</pose>
        <geometry>
          <mesh>
            <scale>1 1 1</scale>
            <uri>model://surgical_robot_description/meshes/vertical_translation.stl</uri>
          </mesh>
        </geometry>
      </collision>
      <visual name='vertical_translation_visual'>
        <pose>0 0 0 0 -0 0</pose>
        <geometry>
          <mesh>
            <scale>1 1 1</scale>
            <uri>model://surgical_robot_description/meshes/vertical_translation_200.stl</uri>
          </mesh>
        </geometry>
      </visual>
      <velocity_decay>
        <linear>0</linear>
        <angular>0</angular>
      </velocity_decay>
    </link>
    <joint name='base_y' type='prismatic'>
      <child>vertical_translation</child>
      <parent>lateral_translation</parent>
      <axis>
        <xyz>-0.999999 0.00159265 0</xyz>
        <limit>
          <lower>0</lower>
          <upper>0.1</upper>
          <effort>0.001</effort>
          <velocity>0.2</velocity>
        </limit>
        <dynamics/>
      </axis>
    </joint>
    <link name='base'>
      <pose>-0.0304616 -0.101419 0.0796502 1.5707 -0 3.14</pose>
      <inertial>
        <pose>0 0 0 0 -0 0</pose>
        <mass>0.5</mass>
        <inertia>
          <ixx>0.001</ixx>
          <ixy>0</ixy>
          <ixz>0</ixz>
          <iyy>0.001</iyy>
          <iyz>0</iyz>
          <izz>0.001</izz>
        </inertia>
      </inertial>
      <collision name='base_collision'>
        <pose>0 0 0 0 -0 0</pose>
        <geometry>
          <mesh>
            <scale>1 1 1</scale>
            <uri>model://surgical_robot_description/meshes/base.stl</uri>
          </mesh>
        </geometry>
      </collision>
      <visual name='base_visual'>
        <pose>0 0 0 0 -0 0</pose>
        <geometry>
          <mesh>
            <scale>1 1 1</scale>
            <uri>model://surgical_robot_description/meshes/base_200.stl</uri>
          </mesh>
        </geometry>
      </visual>
      <velocity_decay>
        <linear>0</linear>
        <angular>0</angular>
      </velocity_decay>
    </link>
    <joint name='base_z' type='prismatic'>
      <child>base</child>
      <parent>vertical_translation</parent>
      <axis>
        <xyz>-1.53415e-07 -9.63267e-05 1</xyz>
        <limit>
          <lower>0</lower>
          <upper>0.1</upper>
          <effort>0.001</effort>
          <velocity>0.2</velocity>
        </limit>
        <dynamics/>
      </axis>
    </joint>
    <link name='base_yaw'>
      <pose>-0.108298 -0.187305 0.181662 1.5707 -0 3.14</pose>
      <inertial>
        <pose>0 0 0 0 -0 0</pose>
        <mass>0.5</mass>
        <inertia>
          <ixx>0.001</ixx>
          <ixy>0</ixy>
          <ixz>0</ixz>
          <iyy>0.001</iyy>
          <iyz>0</iyz>
          <izz>0.001</izz>
        </inertia>
      </inertial>
      <collision name='base_yaw_collision'>
        <pose>0 0 0 0 -0 0</pose>
        <geometry>
          <mesh>
            <scale>1 1 1</scale>
            <uri>model://surgical_robot_description/meshes/base_yaw.stl</uri>
          </mesh>
        </geometry>
      </collision>
      <visual name='base_yaw_visual'>
        <pose>0 0 0 0 -0 0</pose>
        <geometry>
          <mesh>
            <scale>1 1 1</scale>
            <uri>model://surgical_robot_description/meshes/base_yaw_200.stl</uri>
          </mesh>
        </geometry>
      </visual>
      <velocity_decay>
        <linear>0</linear>
        <angular>0</angular>
      </velocity_decay>
    </link>
    <joint name='base_yaw' type='revolute'>
      <child>base_yaw</child>
      <parent>base</parent>
      <axis>
        <xyz>-0.999999 0.00159265 0</xyz>
        <limit>
          <lower>-0.5</lower>
          <upper>0.5</upper>
          <effort>1000</effort>
          <velocity>0.5</velocity>
        </limit>
        <dynamics/>
      </axis>
    </joint>
    <link name='vertical_long'>
      <pose>-0.0869794 -0.150239 0.179646 1.5707 -0 3.14</pose>
      <inertial>
        <pose>0 0 0 0 -0 0</pose>
        <mass>0.5</mass>
        <inertia>
          <ixx>0.001</ixx>
          <ixy>0</ixy>
          <ixz>0</ixz>
          <iyy>0.001</iyy>
          <iyz>0</iyz>
          <izz>0.001</izz>
        </inertia>
      </inertial>
      <collision name='vertical_long_collision'>
        <pose>0 0 0 0 -0 0</pose>
        <geometry>
          <mesh>
            <scale>1 1 1</scale>
            <uri>model://surgical_robot_description/meshes/vertical_long.stl</uri>
          </mesh>
        </geometry>
      </collision>
      <visual name='vertical_long_visual'>
        <pose>0 0 0 0 -0 0</pose>
        <geometry>
          <mesh>
            <scale>1 1 1</scale>
            <uri>model://surgical_robot_description/meshes/vertical_long_200.stl</uri>
          </mesh>
        </geometry>
      </visual>
      <velocity_decay>
        <linear>0</linear>
        <angular>0</angular>
      </velocity_decay>
    </link>
    <joint name='base_vertical_long' type='revolute'>
      <child>vertical_long</child>
      <parent>base_yaw</parent>
      <axis>
        <xyz>0.00159265 0.999999 9.63268e-05</xyz>
        <limit>
          <lower>-0.5</lower>
          <upper>0.5</upper>
          <effort>1000</effort>
          <velocity>0.5</velocity>
        </limit>
        <dynamics/>
      </axis>
    </joint>
    <link name='horizontal_short'>
      <pose>-0.0869659 -0.141748 0.278146 1.5707 -0 3.14</pose>
      <inertial>
        <pose>0 0 0 0 -0 0</pose>
        <mass>0.5</mass>
        <inertia>
          <ixx>0.001</ixx>
          <ixy>0</ixy>
          <ixz>0</ixz>
          <iyy>0.001</iyy>
          <iyz>0</iyz>
          <izz>0.001</izz>
        </inertia>
      </inertial>
      <collision name='horizontal_short_collision'>
        <pose>0 0 0 0 -0 0</pose>
        <geometry>
          <mesh>
            <scale>1 1 1</scale>
            <uri>model://surgical_robot_description/meshes/horizontal_short.stl</uri>
          </mesh>
        </geometry>
      </collision>
      <visual name='horizontal_short_visual'>
        <pose>0 0 0 0 -0 0</pose>
        <geometry>
          <mesh>
            <scale>1 1 1</scale>
            <uri>model://surgical_robot_description/meshes/horizontal_short_200.stl</uri>
          </mesh>
        </geometry>
      </visual>
      <velocity_decay>
        <linear>0</linear>
        <angular>0</angular>
      </velocity_decay>
    </link>
    <joint name='horizontal_s_vertical_l' type='revolute'>
      <child>horizontal_short</child>
      <parent>vertical_long</parent>
      <axis>
        <xyz>0.00159265 0.999999 9.63268e-05</xyz>
        <limit>
          <lower>-0.5</lower>
          <upper>0.5</upper>
          <effort>1000</effort>
          <velocity>0.5</velocity>
        </limit>
        <dynamics/>
      </axis>
    </joint>
    <link name='needle_driver'>
      <pose>-0.246977 -0.148684 0.278146 1.5707 -0 3.14</pose>
      <inertial>
        <pose>0 0 0 0 -0 0</pose>
        <mass>0.5</mass>
        <inertia>
          <ixx>0.001</ixx>
          <ixy>0</ixy>
          <ixz>0</ixz>
          <iyy>0.001</iyy>
          <iyz>0</iyz>
          <izz>0.001</izz>
        </inertia>
      </inertial>
      <visual name='needle_driver_visual'>
        <pose>0 0 0 0 -0 0</pose>
        <geometry>
          <mesh>
            <scale>1 1 1</scale>
            <uri>model://surgical_robot_description/meshes/needle_driver_200.stl</uri>
          </mesh>
        </geometry>
      </visual>
      <velocity_decay>
        <linear>0</linear>
        <angular>0</angular>
      </velocity_decay>
    </link>
    <joint name='horizontal_s_needle_d' type='prismatic'>
      <child>needle_driver</child>
      <parent>horizontal_short</parent>
      <axis>
        <xyz>-1.53415e-07 -9.63267e-05 1</xyz>
        <limit>
          <lower>0</lower>
          <upper>0.1</upper>
          <effort>0.001</effort>
          <velocity>0.2</velocity>
        </limit>
        <dynamics/>
      </axis>
    </joint>
    <link name='horizontal_long'>
      <pose>-0.0869533 -0.133857 0.259647 1.5707 -0 3.14</pose>
      <inertial>
        <pose>0 0 0 0 -0 0</pose>
        <mass>0.5</mass>
        <inertia>
          <ixx>0.001</ixx>
          <ixy>0</ixy>
          <ixz>0</ixz>
          <iyy>0.001</iyy>
          <iyz>0</iyz>
          <izz>0.001</izz>
        </inertia>
      </inertial>
      <collision name='horizontal_long_collision'>
        <pose>0 0 0 0 -0 0</pose>
        <geometry>
          <mesh>
            <scale>1 1 1</scale>
            <uri>model://surgical_robot_description/meshes/horizontal_long.stl</uri>
          </mesh>
        </geometry>
      </collision>
      <visual name='horizontal_long_visual'>
        <pose>0 0 0 0 -0 0</pose>
        <geometry>
          <mesh>
            <scale>1 1 1</scale>
            <uri>model://surgical_robot_description/meshes/horizontal_long_200.stl</uri>
          </mesh>
        </geometry>
      </visual>
      <velocity_decay>
        <linear>0</linear>
        <angular>0</angular>
      </velocity_decay>
    </link>
    <joint name='horizontal_vertical_long' type='revolute'>
      <child>horizontal_long</child>
      <parent>vertical_long</parent>
      <axis>
        <xyz>0.00159265 0.999999 9.63268e-05</xyz>
        <limit>
          <lower>-0.5</lower>
          <upper>0.5</upper>
          <effort>1000</effort>
          <velocity>0.5</velocity>
        </limit>
        <dynamics/>
      </axis>
    </joint>
    <link name='needle_driver'>
      <pose>-0.246965 -0.140792 0.259646 1.5707 -0 3.14</pose>
      <inertial>
        <pose>0 0 0 0 -0 0</pose>
        <mass>0.5</mass>
        <inertia>
          <ixx>0.001</ixx>
          <ixy>0</ixy>
          <ixz>0</ixz>
          <iyy>0.001</iyy>
          <iyz>0</iyz>
          <izz>0.001</izz>
        </inertia>
      </inertial>
      <visual name='needle_driver_visual'>
        <pose>0 0 0 0 -0 0</pose>
        <geometry>
          <mesh>
            <scale>1 1 1</scale>
            <uri>model://surgical_robot_description/meshes/needle_driver_200.stl</uri>
          </mesh>
        </geometry>
      </visual>
      <velocity_decay>
        <linear>0</linear>
        <angular>0</angular>
      </velocity_decay>
    </link>
    <joint name='horizontal_s_needle_d2' type='prismatic'>
      <child>needle_driver</child>
      <parent>horizontal_short</parent>
      <axis>
        <xyz>-1.53415e-07 -9.63267e-05 1</xyz>
        <limit>
          <lower>0</lower>
          <upper>0.1</upper>
          <effort>0.001</effort>
          <velocity>0.2</velocity>
        </limit>
        <dynamics/>
      </axis>
    </joint>
    <link name='vertical_short'>
      <pose>-0.0684667 -0.142268 0.179646 1.5707 -0 3.14</pose>
      <inertial>
        <pose>0 0 0 0 -0 0</pose>
        <mass>0.5</mass>
        <inertia>
          <ixx>0.001</ixx>
          <ixy>0</ixy>
          <ixz>0</ixz>
          <iyy>0.001</iyy>
          <iyz>0</iyz>
          <izz>0.001</izz>
        </inertia>
      </inertial>
      <collision name='vertical_short_collision'>
        <pose>0 0 0 0 -0 0</pose>
        <geometry>
          <mesh>
            <scale>1 1 1</scale>
            <uri>model://surgical_robot_description/meshes/vertical_short.stl</uri>
          </mesh>
        </geometry>
      </collision>
      <visual name='vertical_short_visual'>
        <pose>0 0 0 0 -0 0</pose>
        <geometry>
          <mesh>
            <scale>1 1 1</scale>
            <uri>model://surgical_robot_description/meshes/vertical_short_200.stl</uri>
          </mesh>
        </geometry>
      </visual>
      <velocity_decay>
        <linear>0</linear>
        <angular>0</angular>
      </velocity_decay>
    </link>
    <joint name='base_vertical_short' type='revolute'>
      <child>vertical_short</child>
      <parent>base_yaw</parent>
      <axis>
        <xyz>0.00159265 0.999999 9.63268e-05</xyz>
        <limit>
          <lower>-0.5</lower>
          <upper>0.5</upper>
          <effort>1000</effort>
          <velocity>0.5</velocity>
        </limit>
        <dynamics/>
      </axis>
    </joint>
    <link name='horizontal_long'>
      <pose>-0.0684406 -0.125886 0.259648 1.5707 -0 3.14</pose>
      <inertial>
        <pose>0 0 0 0 -0 0</pose>
        <mass>0.5</mass>
        <inertia>
          <ixx>0.001</ixx>
          <ixy>0</ixy>
          <ixz>0</ixz>
          <iyy>0.001</iyy>
          <iyz>0</iyz>
          <izz>0.001</izz>
        </inertia>
      </inertial>
      <collision name='horizontal_long_collision'>
        <pose>0 0 0 0 -0 0</pose>
        <geometry>
          <mesh>
            <scale>1 1 1</scale>
            <uri>model://surgical_robot_description/meshes/horizontal_long.stl</uri>
          </mesh>
        </geometry>
      </collision>
      <visual name='horizontal_long_visual'>
        <pose>0 0 0 0 -0 0</pose>
        <geometry>
          <mesh>
            <scale>1 1 1</scale>
            <uri>model://surgical_robot_description/meshes/horizontal_long_200.stl</uri>
          </mesh>
        </geometry>
      </visual>
      <velocity_decay>
        <linear>0</linear>
        <angular>0</angular>
      </velocity_decay>
    </link>
    <joint name='horizontal_vertical_long2' type='revolute'>
      <child>horizontal_long</child>
      <parent>vertical_long</parent>
      <axis>
        <xyz>0.00159265 0.999999 9.63268e-05</xyz>
        <limit>
          <lower>-0.5</lower>
          <upper>0.5</upper>
          <effort>1000</effort>
          <velocity>0.5</velocity>
        </limit>
        <dynamics/>
      </axis>
    </joint>
    <link name='needle_driver'>
      <pose>-0.228452 -0.132821 0.259647 1.5707 -0 3.14</pose>
      <inertial>
        <pose>0 0 0 0 -0 0</pose>
        <mass>0.5</mass>
        <inertia>
          <ixx>0.001</ixx>
          <ixy>0</ixy>
          <ixz>0</ixz>
          <iyy>0.001</iyy>
          <iyz>0</iyz>
          <izz>0.001</izz>
        </inertia>
      </inertial>
      <visual name='needle_driver_visual'>
        <pose>0 0 0 0 -0 0</pose>
        <geometry>
          <mesh>
            <scale>1 1 1</scale>
            <uri>model://surgical_robot_description/meshes/needle_driver_200.stl</uri>
          </mesh>
        </geometry>
      </visual>
      <velocity_decay>
        <linear>0</linear>
        <angular>0</angular>
      </velocity_decay>
    </link>
    <joint name='horizontal_s_needle_d3' type='prismatic'>
      <child>needle_driver</child>
      <parent>horizontal_short</parent>
      <axis>
        <xyz>-1.53415e-07 -9.63267e-05 1</xyz>
        <limit>
          <lower>0</lower>
          <upper>0.1</upper>
          <effort>0.001</effort>
          <velocity>0.2</velocity>
        </limit>
        <dynamics/>
      </axis>
    </joint>
    <static>0</static>
    <plugin name='gazebo_ros_control' filename='libgazebo_ros_control.so'>
      <robotNamespace>/surgical_robot_description</robotNamespace>
    </plugin>
  </model>
</sdf>
